Workbook
Name Slicer_Column1: #N/A
Name Slicer_company_name1: #N/A
Name Slicer_Months: #N/A
Name Slicer_Months1: #N/A
Name Slicer_Months2: #N/A
Name Slicer_portfolio_id: #N/A
Name Slicer_portfolio_name1: #N/A
Name Slicer_sector_name: #N/A
Name Slicer_side: #N/A
Name Slicer_side1: #N/A
Name Slicer_trader_id: #N/A
Name Slicer_Trader_Name: #N/A
Name Slicer_Trader_Name1: #N/A

Sheet dim_exchange
A1: exchange_id | B1: exchange_name | C1: country | D1: currency
A2: EXCH01 | B2: NSE | C2: India | D2: INR
A3: EXCH02 | B3: NASDAQ | C3: USA | D3: USD

Sheet dim_sector
A1: sector_id | B1: sector_name
A2: SEC01 | B2: Information Technology
A3: SEC02 | B3: Financials
A4: SEC03 | B4: Healthcare
A5: SEC04 | B5: Energy
A6: SEC05 | B6: Consumer Discretionary

Sheet dim_company
A1: company_id | B1: ticker | C1: company_name | D1: sector_id | E1: exchange_id
A2: COMP001 | B2: TCS | C2: Tata Consultancy Services | D2: SEC01 | E2: EXCH01
A3: COMP002 | B3: INFY | C3: Infosys | D3: SEC01 | E3: EXCH01
A4: COMP003 | B4: HDFCBANK | C4: HDFC Bank | D4: SEC02 | E4: EXCH01
A5: COMP004 | B5: RELIANCE | C5: Reliance Industries | D5: SEC04 | E5: EXCH01
A6: COMP005 | B6: AAPL | C6: Apple Inc. | D6: SEC01 | E6: EXCH02
A7: COMP006 | B7: MSFT | C7: Microsoft Corp. | D7: SEC01 | E7: EXCH02
A8: COMP007 | B8: AMZN | C8: Amazon.com Inc. | D8: SEC05 | E8: EXCH02
A9: COMP008 | B9: PFE | C9: Pfizer Inc. | D9: SEC03 | E9: EXCH02

Sheet dim_trader
A1: trader_id | B1: trader_name | C1: desk
A2: TRD000001 | B2: Taylor Shah | C2: Momentum
A3: TRD000002 | B3: Drew Williams | C3: Alpha
A4: TRD000003 | B4: Avery Garcia | C4: Discretionary
A5: TRD000004 | B5: Taylor Harris | C5: Quant
A6: TRD000005 | B6: Jordan Clark | C6: Discretionary
A7: TRD000006 | B7: Reese Patel | C7: Quant
A8: TRD000007 | B8: Alex Lee | C8: Momentum
A9: TRD000008 | B9: Morgan Williams | C9: Quant
A10: TRD000009 | B10: Robin Lewis | C10: Quant
A11: TRD000010 | B11: Alex Harris | C11: Momentum
A12: TRD000011 | B12: Morgan Harris | C12: Quant
... A31: TRD000030 | B31: Riley Lee | C31: Momentum

Sheet dim_portfolio
A1: portfolio_id | B1: portfolio_name | C1: manager
A2: PF000001 | B2: Portfolio 1 | C2: Skyler Wilson
A3: PF000002 | B3: Portfolio 2 | C3: Rowan Garcia
A4: PF000003 | B4: Portfolio 3 | C4: Drew Garcia
A5: PF000004 | B5: Portfolio 4 | C5: Avery Harris
A6: PF000005 | B6: Portfolio 5 | C6: Kai Brown
A7: PF000006 | B7: Portfolio 6 | C7: Kendall Anderson
A8: PF000007 | B8: Portfolio 7 | C8: Kendall Wilson
A9: PF000008 | B9: Portfolio 8 | C9: Elliot Williams
A10: PF000009 | B10: Portfolio 9 | C10: Casey White
A11: PF000010 | B11: Portfolio 10 | C11: Skyler Lee

Sheet dim_calendar
A1: date | B1: calendar_id | C1: year | D1: month | E1: day | F1: is_month_start
A2: 2025-01-01 | B2: 1 | C2: 2025 | D2: 1 | E2: 1 | F2: TRUE
A3: 2025-01-02 | B3: 2 | C3: 2025 | D3: 1 | E3: 2 | F3: FALSE
A4: 2025-01-03 | B4: 3 | C4: 2025 | D4: 1 | E4: 3 | F4: FALSE
A5: 2025-01-04 | B5: 4 | C5: 2025 | D5: 1 | E5: 4 | F5: FALSE
A6: 2025-01-05 | B6: 5 | C6: 2025 | D6: 1 | E6: 5 | F6: FALSE
A7: 2025-01-06 | B7: 6 | C7: 2025 | D7: 1 | E7: 6 | F7: FALSE
A8: 2025-01-07 | B8: 7 | C8: 2025 | D8: 1 | E8: 7 | F8: FALSE
A9: 2025-01-08 | B9: 8 | C9: 2025 | D9: 1 | E9: 8 | F9: FALSE
A10: 2025-01-09 | B10: 9 | C10: 2025 | D10: 1 | E10: 9 | F10: FALSE
A11: 2025-01-10 | B11: 10 | C11: 2025 | D11: 1 | E11: 10 | F11: FALSE
A12: 2025-01-11 | B12: 11 | C12: 2025 | D12: 1 | E12: 11 | F12: FALSE
A13: 2025-01-12 | B13: 12 | C13: 2025 | D13: 1 | E13: 12 | F13: FALSE
... A182: 2025-06-30 | B182: 181 | C182: 2025 | D182: 6 | E182: 30 | F182: FALSE

Sheet fact_daily_prices
A1: date | B1: company_id | C1: open | D1: high | E1: low | F1: close | G1: volume | H1: calendar_id | I1: cumulative_factor | J1: adjusted_close | K1: avg_vol | L1: is_volume_suspect | M1: prev_close | N1: daily_return_pct
A2: 2025-01-01 | B2: COMP001 | C2: 796.56 | D2: 800.79 | E2: 792.33 | F2: 800.53 | G2: 42106 | H2: 1 | I2: 1.5 | J2: 533.68667 | K2: 25295.845 | L2: FALSE | M2: =IF(Table1[company_id]=OFFSET(Table1[company_id],-1,0), OFFSET(Table1[adjusted_close],-1,0), "") -> 533.68667 | N2: =(J:J- M:M) / M:M -> 0
A3: 2025-01-02 | B3: COMP001 | C3: 805.97 | D3: 809.55 | E3: 802.39 | F3: 803.94 | G3: 9680 | H3: 2 | I3: 1.5 | J3: 535.96 | K3: 25295.845 | L3: FALSE | M3: =IF(Table1[company_id]=OFFSET(Table1[company_id],-1,0), OFFSET(Table1[adjusted_close],-1,0), "") -> 535.96 | N3: =(J:J- M:M) / M:M -> 0
A4: 2025-01-03 | B4: COMP001 | C4: 809.42 | D4: 818.12 | E4: 800.72 | F4: 806.96 | G4: 36153 | H4: 3 | I4: 1.5 | J4: 537.97333 | K4: 25295.845 | L4: FALSE | M4: =IF(Table1[company_id]=OFFSET(Table1[company_id],-1,0), OFFSET(Table1[adjusted_close],-1,0), "") -> 537.97333 | N4: =(J:J- M:M) / M:M -> 0
A5: 2025-01-06 | B5: COMP001 | C5: 818.82 | D5: 831.19 | E5: 806.45 | F5: 817.5 | G5: 9120 | H5: 6 | I5: 1.5 | J5: 545 | K5: 25295.845 | L5: FALSE | M5: =IF(Table1[company_id]=OFFSET(Table1[company_id],-1,0), OFFSET(Table1[adjusted_close],-1,0), "") -> 545 | N5: =(J:J- M:M) / M:M -> 0
A6: 2025-01-07 | B6: COMP001 | C6: 805.15 | D6: 813.57 | E6: 796.72 | F6: 811.73 | G6: 21445 | H6: 7 | I6: 1.5 | J6: 541.15333 | K6: 25295.845 | L6: FALSE | M6: =IF(Table1[company_id]=OFFSET(Table1[company_id],-1,0), OFFSET(Table1[adjusted_close],-1,0), "") -> 541.15333 | N6: =(J:J- M:M) / M:M -> 0
A7: 2025-01-08 | B7: COMP001 | C7: 810.34 | D7: 817.79 | E7: 802.88 | F7: 806.57 | G7: 32065 | H7: 8 | I7: 1.5 | J7: 537.71333 | K7: 25295.845 | L7: FALSE | M7: =IF(Table1[company_id]=OFFSET(Table1[company_id],-1,0), OFFSET(Table1[adjusted_close],-1,0), "") -> 537.71333 | N7: =(J:J- M:M) / M:M -> 0
A8: 2025-01-09 | B8: COMP001 | C8: 804.7 | D8: 816.71 | E8: 792.7 | F8: 800.97 | G8: 46936 | H8: 9 | I8: 1.5 | J8: 533.98 | K8: 25295.845 | L8: FALSE | M8: =IF(Table1[company_id]=OFFSET(Table1[company_id],-1,0), OFFSET(Table1[adjusted_close],-1,0), "") -> 533.98 | N8: =(J:J- M:M) / M:M -> 0
A9: 2025-01-10 | B9: COMP001 | C9: 793.07 | D9: 795.72 | E9: 790.42 | F9: 791.89 | G9: 21932 | H9: 10 | I9: 1.5 | J9: 527.92667 | K9: 25295.845 | L9: FALSE | M9: =IF(Table1[company_id]=OFFSET(Table1[company_id],-1,0), OFFSET(Table1[adjusted_close],-1,0), "") -> 527.92667 | N9: =(J:J- M:M) / M:M -> 0
A10: 2025-01-13 | B10: COMP001 | C10: 768.48 | D10: 780.24 | E10: 756.73 | F10: 766.43 | G10: 44016 | H10: 13 | I10: 1.5 | J10: 510.95333 | K10: 25295.845 | L10: FALSE | M10: =IF(Table1[company_id]=OFFSET(Table1[company_id],-1,0), OFFSET(Table1[adjusted_close],-1,0), "") -> 510.95333 | N10: =(J:J- M:M) / M:M -> 0
A11: 2025-01-14 | B11: COMP001 | C11: 772.58 | D11: 780.18 | E11: 764.98 | F11: 775.85 | G11: 2154 | H11: 14 | I11: 1.5 | J11: 517.23333 | K11: 25295.845 | L11: TRUE | M11: =IF(Table1[company_id]=OFFSET(Table1[company_id],-1,0), OFFSET(Table1[adjusted_close],-1,0), "") -> 517.23333 | N11: =(J:J- M:M) / M:M -> 0
A12: 2025-01-15 | B12: COMP001 | C12: 787.6 | D12: 797.49 | E12: 777.72 | F12: 784.06 | G12: 13183 | H12: 15 | I12: 1.5 | J12: 522.70667 | K12: 25295.845 | L12: FALSE | M12: =IF(Table1[company_id]=OFFSET(Table1[company_id],-1,0), OFFSET(Table1[adjusted_close],-1,0), "") -> 522.70667 | N12: =(J:J- M:M) / M:M -> 0
A13: 2025-01-16 | B13: COMP001 | C13: 768.68 | D13: 782.43 | E13: 754.94 | F13: 769.33 | G13: 6539 | H13: 16 | I13: 1.5 | J13: 512.88667 | K13: 25295.845 | L13: FALSE | M13: =IF(Table1[company_id]=OFFSET(Table1[company_id],-1,0), OFFSET(Table1[adjusted_close],-1,0), "") -> 512.88667 | N13: =(J:J- M:M) / M:M -> 0
... A1033: 2025-06-30 | B1033: COMP008 | C1033: 1378.34 | D1033: 1385.28 | E1033: 1371.39 | F1033: 1377.18 | G1033: 24238 | H1033: 181 | I1033: 1 | J1033: 1377.18 | K1033: 24664.891 | L1033: FALSE | M1033: =IF(Table1[company_id]=OFFSET(Table1[company_id],-1,0), OFFSET(Table1[adjusted_close],-1,0), "") -> #VALUE! | N1033: =(J:J- M:M) / M:M -> #VALUE!

Sheet fact_dividends
A1: date | B1: company_id | C1: dividend_per_share | D1: calendar_id | E1: exchange_id | F1: is_orphan_dividend
A2: 2025-06-30 | B2: COMP001 | C2: 17.05 | D2: 181 | E2: EXCH01 | F2: FALSE
A3: 2025-06-30 | B3: COMP002 | C3: 17.6 | D3: 181 | E3: EXCH01 | F3: FALSE
A4: 2025-03-31 | B4: COMP003 | C4: 12.5 | D4: 90 | E4: EXCH01 | F4: FALSE
A5: 2025-03-31 | B5: COMP006 | C5: 4.37 | D5: 90 | E5: EXCH02 | F5: FALSE
A6: 2025-06-30 | B6: COMP006 | C6: 22.35 | D6: 181 | E6: EXCH02 | F6: FALSE
A7: 2025-03-31 | B7: COMP007 | C7: 20.39 | D7: 90 | E7: EXCH02 | F7: FALSE
A8: 2025-06-30 | B8: COMP007 | C8: 13.49 | D8: 181 | E8: EXCH02 | F8: FALSE
A9: 2025-06-30 | B9: COMP008 | C9: 12.25 | D9: 181 | E9: EXCH02 | F9: FALSE

Sheet fact_splits
A1: company_id | B1: date | C1: split_ratio | D1: calendar_id | E1: exchange_id
A2: COMP004 | B2: 2025-05-21 | C2: 1.5 | D2: 141 | E2: EXCH01
A3: COMP008 | B3: 2025-05-16 | C3: 2 | D3: 136 | E3: EXCH02
A4: COMP004 | B4: 2025-06-13 | C4: 2 | D4: 164 | E4: EXCH01
A5: COMP001 | B5: 2025-05-20 | C5: 1.5 | D5: 140 | E5: EXCH01
A6: COMP008 | B6: 2025-05-05 | C6: 2 | D6: 125 | E6: EXCH02

Sheet fact_orders
A1: order_id | B1: order_ts | C1: company_id | D1: side | E1: quantity | F1: status | G1: order_type | H1: trader_id | I1: portfolio_id | J1: date | K1: calendar_id | L1: order_ts_imputed | M1: limit_price_imputed | N1: portfolio_id_imputed
A2: ORD00001 | B2: 2025-02-25 | C2: COMP002 | D2: BUY | E2: 827 | F2: FILLED | G2: MARKET | H2: TRD000004 | I2: PF000006 | J2: 2025-02-28 | K2: 59 | L2: FALSE | M2: TRUE | N2: FALSE
A3: ORD00002 | B3: 2025-03-10 | C3: COMP006 | D3: BUY | E3: 665 | F3: FILLED | G3: MARKET | H3: TRD000007 | I3: PF000006 | J3: 2025-05-14 | K3: 134 | L3: FALSE | M3: TRUE | N3: FALSE
A4: ORD00003 | B4: 2025-06-24 | C4: COMP007 | D4: SELL | E4: 787 | F4: FILLED | G4: MARKET | H4: TRD000020 | I4: PF000006 | J4: 2025-05-23 | K4: 143 | L4: FALSE | M4: TRUE | N4: FALSE
A5: ORD00004 | B5: 2025-01-30 | C5: COMP002 | D5: BUY | E5: 194 | F5: FILLED | G5: MARKET | H5: TRD000006 | I5: PF000009 | J5: 2025-05-28 | K5: 148 | L5: FALSE | M5: TRUE | N5: FALSE
A6: ORD00005 | B6: 2025-05-05 | C6: COMP003 | D6: BUY | E6: 331 | F6: FILLED | G6: MARKET | H6: TRD000019 | I6: PF000008 | J6: 2025-03-07 | K6: 66 | L6: FALSE | M6: TRUE | N6: FALSE
A7: ORD00006 | B7: 2025-04-02 | C7: COMP001 | D7: BUY | E7: 330 | F7: FILLED | G7: MARKET | H7: TRD000012 | I7: PF000006 | J7: 2025-02-25 | K7: 56 | L7: FALSE | M7: TRUE | N7: FALSE
A8: ORD00007 | B8: 2025-04-18 | C8: COMP006 | D8: BUY | E8: 203 | F8: FILLED | G8: MARKET | H8: TRD000002 | I8: PF000002 | J8: 2025-06-11 | K8: 162 | L8: FALSE | M8: TRUE | N8: FALSE
A9: ORD00008 | B9: 2025-06-27 | C9: COMP008 | D9: BUY | E9: 323 | F9: FILLED | G9: MARKET | H9: TRD000006 | I9: PF000009 | J9: 2025-05-01 | K9: 121 | L9: FALSE | M9: TRUE | N9: FALSE
A10: ORD00009 | B10: 2025-06-26 | C10: COMP005 | D10: SELL | E10: 857 | F10: FILLED | G10: MARKET | H10: TRD000016 | I10: PF000002 | J10: 2025-05-26 | K10: 146 | L10: FALSE | M10: TRUE | N10: FALSE
A11: ORD00010 | B11: 2025-05-26 | C11: COMP008 | D11: BUY | E11: 764 | F11: FILLED | G11: MARKET | H11: TRD000030 | I11: PF000007 | J11: 2025-04-11 | K11: 101 | L11: FALSE | M11: TRUE | N11: FALSE
A12: ORD00011 | B12: 2025-05-01 | C12: COMP008 | D12: BUY | E12: 151 | F12: FILLED | G12: MARKET | H12: TRD000016 | I12: PF000009 | J12: 2025-02-26 | K12: 57 | L12: FALSE | M12: TRUE | N12: FALSE
A13: ORD00012 | B13: 2025-04-21 | C13: COMP001 | D13: BUY | E13: 52 | F13: FILLED | G13: MARKET | H13: TRD000015 | I13: PF000002 | J13: 2025-06-06 | K13: 157 | L13: FALSE | M13: TRUE | N13: FALSE
... A501: ORD00500 | B501: 2025-04-18 | C501: COMP004 | D501: BUY | E501: 902 | F501: FILLED | G501: MARKET | H501: TRD000015 | I501: PF000003 | J501: 2025-04-02 | K501: 92 | L501: FALSE | M501: TRUE | N501: FALSE

Sheet fact_trades
A1: trade_id | B1: order_id | C1: trade_ts | D1: company_id | E1: side | F1: quantity | G1: price | H1: fees | I1: trader_id | J1: portfolio_id | K1: date | L1: calendar_id | M1: trade_ts_imputed | N1: fees_imputed | O1: portfolio_id_imputed | P1: is_orphan_trade
A2: TR_SYN_0000001 | B2: ORD00044 | C2: 2025-02-25 00:28:00 | D2: COMP005 | E2: BUY | F2: 827 | G2: 231.66 | H2: 95.79 | I2: TRD000028 | J2: PF000009 | K2: 2025-05-09 | L2: 129 | M2: FALSE | N2: FALSE | O2: FALSE | P2: FALSE
A3: TR_SYN_0000002 | B3: ORD00147 | C3: 2025-03-10 00:34:00 | D3: COMP008 | E3: BUY | F3: 665 | G3: 1099.75 | H3: 365.67 | I3: TRD000010 | J3: PF000004 | K3: 2025-01-24 | L3: 24 | M3: FALSE | N3: FALSE | O3: FALSE | P3: FALSE
A4: TR_SYN_0000003 | B4: ORD00281 | C4: 2025-06-24 00:59:00 | D4: COMP003 | E4: SELL | F4: 787 | G4: 2156.16 | H4: 848.45 | I4: TRD000012 | J4: PF000007 | K4: 2025-02-26 | L4: 57 | M4: FALSE | N4: FALSE | O4: FALSE | P4: FALSE
A5: TR_SYN_0000004 | B5: ORD00014 | C5: 2025-01-30 00:57:00 | D5: COMP004 | E5: BUY | F5: 194 | G5: 604.46 | H5: 58.63 | I5: TRD000016 | J5: PF000010 | K5: 2025-06-12 | L5: 163 | M5: FALSE | N5: FALSE | O5: FALSE | P5: FALSE
A6: TR_SYN_0000005 | B6: ORD00023 | C6: 2025-05-05 00:46:00 | D6: COMP008 | E6: BUY | F6: 331 | G6: 1369.91 | H6: 226.72 | I6: TRD000017 | J6: PF000010 | K6: 2025-01-16 | L6: 16 | M6: FALSE | N6: FALSE | O6: FALSE | P6: FALSE
A7: TR_SYN_0000006 | B7: ORD00390 | C7: 2025-04-02 00:32:00 | D7: COMP005 | E7: BUY | F7: 330 | G7: 246.17 | H7: 40.62 | I7: TRD000026 | J7: PF000007 | K7: 2025-04-15 | L7: 105 | M7: FALSE | N7: FALSE | O7: FALSE | P7: FALSE
A8: TR_SYN_0000007 | B8: ORD00249 | C8: 2025-04-18 00:36:00 | D8: COMP006 | E8: BUY | F8: 203 | G8: 241.39 | H8: 24.5 | I8: TRD000020 | J8: PF000003 | K8: 2025-04-16 | L8: 106 | M8: FALSE | N8: FALSE | O8: FALSE | P8: FALSE
A9: TR_SYN_0000008 | B9: ORD00476 | C9: 2025-06-27 00:32:00 | D9: COMP001 | E9: BUY | F9: 323 | G9: 784.63 | H9: 126.72 | I9: TRD000030 | J9: PF000002 | K9: 2025-03-04 | L9: 63 | M9: FALSE | N9: FALSE | O9: FALSE | P9: FALSE
A10: TR_SYN_0000009 | B10: ORD00374 | C10: 2025-06-26 00:03:00 | D10: COMP005 | E10: SELL | F10: 857 | G10: 255.49 | H10: 109.48 | I10: TRD000027 | J10: PF000009 | K10: 2025-01-02 | L10: 2 | M10: FALSE | N10: FALSE | O10: FALSE | P10: FALSE
A11: TR_SYN_0000010 | B11: ORD00377 | C11: 2025-05-26 00:02:00 | D11: COMP007 | E11: BUY | F11: 764 | G11: 608.33 | H11: 232.38 | I11: TRD000002 | J11: PF000007 | K11: 2025-03-18 | L11: 77 | M11: FALSE | N11: FALSE | O11: FALSE | P11: FALSE
A12: TR_SYN_0000011 | B12: ORD00063 | C12: 2025-05-01 00:47:00 | D12: COMP002 | E12: BUY | F12: 151 | G12: 1209.1 | H12: 91.29 | I12: TRD000002 | J12: PF000001 | K12: 2025-06-02 | L12: 153 | M12: FALSE | N12: FALSE | O12: FALSE | P12: FALSE
A13: TR_SYN_0000012 | B13: ORD00369 | C13: 2025-04-21 00:56:00 | D13: COMP001 | E13: BUY | F13: 52 | G13: 798.26 | H13: 20.75 | I13: TRD000003 | J13: PF000003 | K13: 2025-04-18 | L13: 108 | M13: FALSE | N13: FALSE | O13: FALSE | P13: FALSE
... A501: TR_SYN_0000500 | B501: ORD00463 | C501: 2025-04-18 00:58:00 | D501: COMP005 | E501: BUY | F501: 902 | G501: 256.23 | H501: 115.56 | I501: TRD000025 | J501: PF000006 | K501: 2025-05-02 | L501: 122 | M501: FALSE | N501: FALSE | O501: FALSE | P501: FALSE

Sheet fact_positions_snapshot
A1: portfolio_id | B1: company_id | C1: date | D1: quantity | E1: calendar_id
A2: PF000010 | B2: COMP007 | C2: 2025-02-18 | D2: 916 | E2: 49
A3: PF000007 | B3: COMP003 | C3: 2025-04-16 | D3: 202 | E3: 106
A4: PF000007 | B4: COMP006 | C4: 2025-03-21 | D4: 833 | E4: 80
A5: PF000001 | B5: COMP004 | C5: 2025-02-28 | D5: 908 | E5: 59
A6: PF000002 | B6: COMP008 | C6: 2025-02-19 | D6: 809 | E6: 50
A7: PF000008 | B7: COMP004 | C7: 2025-02-21 | D7: 345 | E7: 52
A8: PF000005 | B8: COMP001 | C8: 2025-06-05 | D8: 934 | E8: 156
A9: PF000004 | B9: COMP001 | C9: 2025-04-29 | D9: 618 | E9: 119
A10: PF000008 | B10: COMP006 | C10: 2025-01-10 | D10: 896 | E10: 10
A11: PF000009 | B11: COMP003 | C11: 2025-02-27 | D11: 479 | E11: 58

Sheet stocks 
A1: ticker | B1: company_name | C1: exchange | D1: sector | E1: currency | F1: share_price | G1: outstanding_shares | H1: market_cap | I1: quantity | J1: buy_price | K1: initial_value | L1: current_price | M1: current_value | N1: return_pct
A2: INFY | B2: Infosys Ltd | C2: NSE | D2: IT | E2: INR | F2: 1500 | G2: 31800 | H2: 477000 | I2: 51 | J2: 1362.55 | K2: 69490.048 | L2: 1500 | M2: 76500 | N2: 10.087706
A3: TCS | B3: Tata Consultancy Services | C3: NSE | D3: IT | E3: INR | F3: 3200 | G3: 36000 | H3: 1152000 | I3: 75 | J3: 2918.0183 | K3: 218851.37 | L3: 3200 | M3: 240000 | N3: 9.663466
A4: HDFC | B4: HDFC Bank | C4: NSE | D4: Financials | E4: INR | F4: 1450 | G4: 25000 | H4: 36250000 | I4: 14 | J4: 1395.8941 | K4: 19542.517 | L4: 1450 | M4: 20300 | N4: 3.8760768
A5: RELI | B5: Reliance Industries | C5: NSE | D5: Energy | E5: INR | F5: 2600 | G5: 64000 | H5: 166400000 | I5: 178 | J5: 2222.4858 | K5: 395602.47 | L5: 2600 | M5: 462800 | N5: 16.986124
A6: WIPRO | B6: Wipro Ltd | C6: NSE | D6: IT | E6: INR | F6: 400 | G6: 22000 | H6: 8800000 | I6: 102 | J6: 385.46356 | K6: 39317.283 | L6: 400 | M6: 40800 | N6: 3.7711572
A7: AAPL | B7: Apple Inc | C7: NASDAQ | D7: Technology | E7: USD | F7: 170 | G7: 16000 | H7: 27200000 | I7: 42 | J7: 145.1021 | K7: 6094.2881 | L7: 170 | M7: 7140 | N7: 17.158886
A8: MSFT | B8: Microsoft Corp | C8: NASDAQ | D8: Technology | E8: USD | F8: 370 | G8: 76000 | H8: 28120000 | I8: 142 | J8: 316.1934 | K8: 44899.463 | L8: 370 | M8: 52540 | N8: 17.016989
A9: AMZN | B9: Amazon.com Inc | C9: NASDAQ | D9: Consumer Discretionary | E9: USD | F9: 140 | G9: 10000 | H9: 1400000 | I9: 82 | J9: 133.08007 | K9: 10912.566 | L9: 140 | M9: 11480 | N9: 5.1998216
A10: GOOGL | B10: Alphabet Inc | C10: NASDAQ | D10: Communication Services | E10: USD | F10: 130 | G10: 30000 | H10: 39000 | I10: 93 | J10: 121.09456 | K10: 11261.794 | L10: 130 | M10: 12090 | N10: 7.3541177
A11: TSLA | B11: Tesla Inc | C11: NASDAQ | D11: Automotive | E11: USD | F11: 220 | G11: 30000 | H11: 660000 | I11: 93 | J11: 202.6487 | K11: 18846.329 | L11: 220 | M11: 20460 | N11: 8.5622579

Sheet fact_trades_pnl_kpi
A1: portfolio_id | B1: company_id | C1: sell_trade_id | D1: trader_id | E1: sell_date | F1: calendar_id | G1: sell_price | H1: quantity_sold | I1: gross_sell_amount | J1: gross_buy_amount | K1: allocated_buy_fees | L1: allocated_sell_fees | M1: total_fees_allocated | N1: avg_buy_price | O1: total_cost_basis | P1: realized_profit | Q1: return_pct | R1: win_flag | S1: net_profit | T1: Months
A2: PF000001 | B2: COMP001 | C2: TR_SYN_0000249 | D2: TRD000004 | E2: 2025-01-20 | F2: 20 | G2: 754.85 | H2: 121 | I2: 91336.85 | J2: 91453.01 | K2: 45.727143 | L2: 45.67 | M2: 91.397143 | N2: 756.18791 | O2: 91498.737 | P2: -207.55714 | Q2: -0.0022684154 | R2: 0 | S2: =(tbl_pnl[gross_sell_amount] - tbl_pnl[total_cost_basis] - tbl_pnl[total_fees_allocated]) -> -253.28429 | T2: =TEXT(E2,"mmm") -> Jan | U2: Total Realized P&L | W2: =_xlfn.STDEV.S(Q:Q) -> 0.90630355
A3: PF000001 | B3: COMP001 | C3: TR_SYN_0000196 | D3: TRD000025 | E3: 2025-03-10 | F3: 69 | G3: 821.15 | H3: 472 | I3: 387582.8 | J3: 356742.32 | K3: 178.37365 | L3: 193.79 | M3: 372.16365 | N3: 756.18791 | O3: 356920.69 | P3: 30468.316 | Q3: 0.085364387 | R3: 1 | S3: =(tbl_pnl[gross_sell_amount] - tbl_pnl[total_cost_basis] - tbl_pnl[total_fees_allocated]) -> 30289.943 | T3: =TEXT(E3,"mmm") -> Mar | U3: =SUM(tbl_pnl[net_profit]) -> 60767204
A4: PF000001 | B4: COMP001 | C4: TR_SYN_0000163 | D4: TRD000007 | E4: 2025-06-24 | F4: 175 | G4: 814.88 | H4: 923 | I4: 752134.24 | J4: 701230.34 | K4: 350.61222 | L4: 376.07 | M4: 726.68222 | N4: 760.10937 | O4: 701580.95 | P4: 50177.218 | Q4: 0.071520211 | R4: 1 | S4: =(tbl_pnl[gross_sell_amount] - tbl_pnl[total_cost_basis] - tbl_pnl[total_fees_allocated]) -> 49826.606 | T4: =TEXT(E4,"mmm") -> Jun
A5: PF000001 | B5: COMP002 | C5: TR_SYN_0000454 | D5: TRD000019 | E5: 2025-06-16 | F5: 167 | G5: 1317.94 | H5: 280 | I5: 369023.2 | J5: 323671.6 | K5: 161.83767 | L5: 184.51 | M5: 346.34767 | N5: 1156.548 | O5: 323833.44 | P5: 45005.252 | Q5: 0.13897655 | R5: 1 | S5: =(tbl_pnl[gross_sell_amount] - tbl_pnl[total_cost_basis] - tbl_pnl[total_fees_allocated]) -> 44843.415 | T5: =TEXT(E5,"mmm") -> Jun
A6: PF000001 | B6: COMP002 | C6: TR_SYN_0000210 | D6: TRD000010 | E6: 2025-01-17 | F6: 17 | G6: 1336.02 | H6: 298 | I6: 398133.96 | J6: 344479.06 | K6: 172.24152 | L6: 199.07 | M6: 371.31152 | N6: 1156.548 | O6: 344651.3 | P6: 53283.588 | Q6: 0.15460144 | R6: 1 | S6: =(tbl_pnl[gross_sell_amount] - tbl_pnl[total_cost_basis] - tbl_pnl[total_fees_allocated]) -> 53111.347 | T6: =TEXT(E6,"mmm") -> Jan | U6: Average Return %
A7: PF000001 | B7: COMP002 | C7: TR_SYN_0000345 | D7: TRD000029 | E7: 2025-02-26 | F7: 57 | G7: 1185.76 | H7: 53 | I7: 62845.28 | J7: 61266.41 | K7: 30.63356 | L7: 31.42 | M7: 62.05356 | N7: 1156.548 | O7: 61297.044 | P7: 1516.8164 | Q7: 0.024745344 | R7: 1 | S7: =(tbl_pnl[gross_sell_amount] - tbl_pnl[total_cost_basis] - tbl_pnl[total_fees_allocated]) -> 1486.1829 | T7: =TEXT(E7,"mmm") -> Feb | U7: =AVERAGE(tbl_pnl[return_pct]) -> 0.2721182
A8: PF000001 | B8: COMP002 | C8: TR_SYN_0000358 | D8: TRD000014 | E8: 2025-03-31 | F8: 90 | G8: 1215.01 | H8: 783 | I8: 951352.83 | J8: 287767.37 | K8: 143.88724 | L8: 475.68 | M8: 619.56724 | N8: 367.70276 | O8: 287911.26 | P8: 662965.89 | Q8: 2.3026744 | R8: 1 | S8: =(tbl_pnl[gross_sell_amount] - tbl_pnl[total_cost_basis] - tbl_pnl[total_fees_allocated]) -> 662822.01 | T8: =TEXT(E8,"mmm") -> Mar
A9: PF000001 | B9: COMP002 | C9: TR_SYN_0000489 | D9: TRD000027 | E9: 2025-02-07 | F9: 38 | G9: 1306.9 | H9: 867 | I9: 1133082.3 | J9: 0 | K9: 0 | L9: 566.54 | M9: 566.54 | N9: 0 | O9: 0 | P9: 1132515.8 | Q9: 0 | R9: 1 | S9: =(tbl_pnl[gross_sell_amount] - tbl_pnl[total_cost_basis] - tbl_pnl[total_fees_allocated]) -> 1132515.8 | T9: =TEXT(E9,"mmm") -> Feb
A10: PF000001 | B10: COMP003 | C10: TR_SYN_0000017 | D10: TRD000028 | E10: 2025-03-18 | F10: 77 | G10: 2239.99 | H10: 213 | I10: 477117.87 | J10: 443354.37 | K10: 221.68029 | L10: 238.56 | M10: 460.24029 | N10: 2082.5167 | O10: 443576.05 | P10: 33303.26 | Q10: 0.07507903 | R10: 1 | S10: =(tbl_pnl[gross_sell_amount] - tbl_pnl[total_cost_basis] - tbl_pnl[total_fees_allocated]) -> 33081.579 | T10: =TEXT(E10,"mmm") -> Mar | U10: Win Rate %
A11: PF000001 | B11: COMP004 | C11: TR_SYN_0000216 | D11: TRD000003 | E11: 2025-02-27 | F11: 58 | G11: 608.29 | H11: 903 | I11: 549285.87 | J11: 0 | K11: 0 | L11: 274.64 | M11: 274.64 | N11: 0 | O11: 0 | P11: 549011.23 | Q11: 0 | R11: 1 | S11: =(tbl_pnl[gross_sell_amount] - tbl_pnl[total_cost_basis] - tbl_pnl[total_fees_allocated]) -> 549011.23 | T11: =TEXT(E11,"mmm") -> Feb | U11: =COUNTIF(tbl_pnl[win_flag],1) / COUNTA(tbl_pnl[win_flag]) -> 0.88702929
A12: PF000001 | B12: COMP004 | C12: TR_SYN_0000396 | D12: TRD000001 | E12: 2025-05-22 | F12: 142 | G12: 630.6 | H12: 955 | I12: 602223 | J12: 0 | K12: 0 | L12: 301.11 | M12: 301.11 | N12: 0 | O12: 0 | P12: 601921.89 | Q12: 0 | R12: 1 | S12: =(tbl_pnl[gross_sell_amount] - tbl_pnl[total_cost_basis] - tbl_pnl[total_fees_allocated]) -> 601921.89 | T12: =TEXT(E12,"mmm") -> May
A13: PF000001 | B13: COMP004 | C13: TR_SYN_0000415 | D13: TRD000004 | E13: 2025-05-30 | F13: 150 | G13: 647.63 | H13: 787 | I13: 509684.81 | J13: 0 | K13: 0 | L13: 254.84 | M13: 254.84 | N13: 0 | O13: 0 | P13: 509429.97 | Q13: 0 | R13: 1 | S13: =(tbl_pnl[gross_sell_amount] - tbl_pnl[total_cost_basis] - tbl_pnl[total_fees_allocated]) -> 509429.97 | T13: =TEXT(E13,"mmm") -> May
A14: PF000001 | B14: COMP004 | C14: TR_SYN_0000103 | D14: TRD000007 | E14: 2025-04-24 | F14: 114 | G14: 639.54 | H14: 307 | I14: 196338.78 | J14: 200133.3 | K14: 100.0681 | L14: 98.17 | M14: 198.2381 | N14: 652.22595 | O14: 200233.37 | P14: -3992.7581 | Q14: -0.019940523 | R14: 0 | S14: =(tbl_pnl[gross_sell_amount] - tbl_pnl[total_cost_basis] - tbl_pnl[total_fees_allocated]) -> -4092.8262 | T14: =TEXT(E14,"mmm") -> Apr | U14: Total Trades Closed
A15: PF000001 | B15: COMP004 | C15: TR_SYN_0000290 | D15: TRD000023 | E15: 2025-06-18 | F15: 169 | G15: 645.04 | H15: 16 | I15: 10320.64 | J15: 10430.4 | K15: 5.2152758 | L15: 5.16 | M15: 10.375276 | N15: 652.22595 | O15: 10435.615 | P15: -120.13528 | Q15: -0.011512045 | R15: 0 | S15: =(tbl_pnl[gross_sell_amount] - tbl_pnl[total_cost_basis] - tbl_pnl[total_fees_allocated]) -> -125.35055 | T15: =TEXT(E15,"mmm") -> Jun | U15: =COUNTA(tbl_pnl[sell_trade_id]) -> 239
A16: PF000001 | B16: COMP005 | C16: TR_SYN_0000080 | D16: TRD000001 | E16: 2025-05-19 | F16: 139 | G16: 226.98 | H16: 551 | I16: 125065.98 | J16: 0 | K16: 0 | L16: 62.53 | M16: 62.53 | N16: 0 | O16: 0 | P16: 125003.45 | Q16: 0 | R16: 1 | S16: =(tbl_pnl[gross_sell_amount] - tbl_pnl[total_cost_basis] - tbl_pnl[total_fees_allocated]) -> 125003.45 | T16: =TEXT(E16,"mmm") -> May
A17: PF000001 | B17: COMP006 | C17: TR_SYN_0000238 | D17: TRD000011 | E17: 2025-02-14 | F17: 45 | G17: 238.22 | H17: 507 | I17: 120777.54 | J17: 106744.96 | K17: 53.37 | L17: 60.39 | M17: 113.76 | N17: 210.64759 | O17: 106798.33 | P17: 13918.82 | Q17: 0.13032807 | R17: 1 | S17: =(tbl_pnl[gross_sell_amount] - tbl_pnl[total_cost_basis] - tbl_pnl[total_fees_allocated]) -> 13865.45 | T17: =TEXT(E17,"mmm") -> Feb
A18: PF000001 | B18: COMP006 | C18: TR_SYN_0000306 | D18: TRD000001 | E18: 2025-05-28 | F18: 148 | G18: 238.43 | H18: 380 | I18: 90603.4 | J18: 89383.6 | K18: 44.693578 | L18: 45.3 | M18: 89.993578 | N18: 235.33761 | O18: 89428.294 | P18: 1129.8064 | Q18: 0.012633657 | R18: 1 | S18: =(tbl_pnl[gross_sell_amount] - tbl_pnl[total_cost_basis] - tbl_pnl[total_fees_allocated]) -> 1085.1128 | T18: =TEXT(E18,"mmm") -> May | U18: Best Trade P&L
A19: PF000001 | B19: COMP006 | C19: TR_SYN_0000284 | D19: TRD000017 | E19: 2025-04-29 | F19: 119 | G19: 246.71 | H19: 289 | I19: 71299.19 | J19: 38811.3 | K19: 19.406422 | L19: 35.65 | M19: 55.056422 | N19: 134.36231 | O19: 38830.706 | P19: 32432.834 | Q19: 0.83523676 | R19: 1 | S19: =(tbl_pnl[gross_sell_amount] - tbl_pnl[total_cost_basis] - tbl_pnl[total_fees_allocated]) -> 32413.427 | T19: =TEXT(E19,"mmm") -> Apr | U19: =MAX(tbl_pnl[net_profit]) -> 1696049.5
A20: PF000001 | B20: COMP006 | C20: TR_SYN_0000374 | D20: TRD000018 | E20: 2025-03-14 | F20: 73 | G20: 225.61 | H20: 819 | I20: 184774.59 | J20: 0 | K20: 0 | L20: 92.39 | M20: 92.39 | N20: 0 | O20: 0 | P20: 184682.2 | Q20: 0 | R20: 1 | S20: =(tbl_pnl[gross_sell_amount] - tbl_pnl[total_cost_basis] - tbl_pnl[total_fees_allocated]) -> 184682.2 | T20: =TEXT(E20,"mmm") -> Mar
A21: PF000001 | B21: COMP006 | C21: TR_SYN_0000381 | D21: TRD000001 | E21: 2025-05-13 | F21: 133 | G21: 244.75 | H21: 570 | I21: 139507.5 | J21: 0 | K21: 0 | L21: 69.75 | M21: 69.75 | N21: 0 | O21: 0 | P21: 139437.75 | Q21: 0 | R21: 1 | S21: =(tbl_pnl[gross_sell_amount] - tbl_pnl[total_cost_basis] - tbl_pnl[total_fees_allocated]) -> 139437.75 | T21: =TEXT(E21,"mmm") -> May
A22: PF000001 | B22: COMP007 | C22: TR_SYN_0000179 | D22: TRD000010 | E22: 2025-01-24 | F22: 24 | G22: 495.01 | H22: 104 | I22: 51481.04 | J22: 46849.92 | K22: 23.424149 | L22: 25.74 | M22: 49.164149 | N22: 450.70523 | O22: 46873.344 | P22: 4581.9559 | Q22: 0.097751845 | R22: 1 | S22: =(tbl_pnl[gross_sell_amount] - tbl_pnl[total_cost_basis] - tbl_pnl[total_fees_allocated]) -> 4558.5317 | T22: =TEXT(E22,"mmm") -> Jan | U22: Worst Trade P&L
A23: PF000001 | B23: COMP007 | C23: TR_SYN_0000445 | D23: TRD000029 | E23: 2025-06-11 | F23: 162 | G23: 540.3 | H23: 848 | I23: 458174.4 | J23: 98655.12 | K23: 49.325851 | L23: 229.09 | M23: 278.41585 | N23: 116.39675 | O23: 98704.446 | P23: 359240.86 | Q23: 3.6395611 | R23: 1 | S23: =(tbl_pnl[gross_sell_amount] - tbl_pnl[total_cost_basis] - tbl_pnl[total_fees_allocated]) -> 359191.54 | T23: =TEXT(E23,"mmm") -> Jun | U23: =MIN(tbl_pnl[net_profit]) -> -16452.454
A24: PF000001 | B24: COMP007 | C24: TR_SYN_0000077 | D24: TRD000005 | E24: 2025-06-09 | F24: 160 | G24: 602.63 | H24: 880 | I24: 530314.4 | J24: 495276.66 | K24: 247.63 | L24: 265.16 | M24: 512.79 | N24: 563.09578 | O24: 495524.29 | P24: 34524.95 | Q24: 0.069673577 | R24: 1 | S24: =(tbl_pnl[gross_sell_amount] - tbl_pnl[total_cost_basis] - tbl_pnl[total_fees_allocated]) -> 34277.32 | T24: =TEXT(E24,"mmm") -> Jun
A25: PF000001 | B25: COMP008 | C25: TR_SYN_0000279 | D25: TRD000003 | E25: 2025-03-03 | F25: 62 | G25: 1105.99 | H25: 782 | I25: 864884.18 | J25: 812357.24 | K25: 406.17809 | L25: 432.44 | M25: 838.61809 | N25: 1039.3394 | O25: 812763.42 | P25: 51688.322 | Q25: 0.063595778 | R25: 1 | S25: =(tbl_pnl[gross_sell_amount] - tbl_pnl[total_cost_basis] - tbl_pnl[total_fees_allocated]) -> 51282.144 | T25: =TEXT(E25,"mmm") -> Mar
A26: PF000001 | B26: COMP008 | C26: TR_SYN_0000442 | D26: TRD000012 | E26: 2025-06-13 | F26: 164 | G26: 1446.06 | H26: 390 | I26: 563963.4 | J26: 441860.55 | K26: 220.93052 | L26: 281.98 | M26: 502.91052 | N26: 1133.5423 | O26: 442081.48 | P26: 121599.94 | Q26: 0.27506228 | R26: 1 | S26: =(tbl_pnl[gross_sell_amount] - tbl_pnl[total_cost_basis] - tbl_pnl[total_fees_allocated]) -> 121379.01 | T26: =TEXT(E26,"mmm") -> Jun
A27: PF000002 | B27: COMP001 | C27: TR_SYN_0000034 | D27: TRD000029 | E27: 2025-01-16 | F27: 16 | G27: 727.77 | H27: 560 | I27: 407551.2 | J27: 210302.12 | K27: 105.15 | L27: 203.78 | M27: 308.93 | N27: 375.72727 | O27: 210407.27 | P27: 196940.15 | Q27: 0.93599499 | R27: 1 | S27: =(tbl_pnl[gross_sell_amount] - tbl_pnl[total_cost_basis] - tbl_pnl[total_fees_allocated]) -> 196835 | T27: =TEXT(E27,"mmm") -> Jan
A28: PF000002 | B28: COMP001 | C28: TR_SYN_0000257 | D28: TRD000016 | E28: 2025-02-13 | F28: 44 | G28: 756.15 | H28: 702 | I28: 530817.3 | J28: 0 | K28: 0 | L28: 265.41 | M28: 265.41 | N28: 0 | O28: 0 | P28: 530551.89 | Q28: 0 | R28: 1 | S28: =(tbl_pnl[gross_sell_amount] - tbl_pnl[total_cost_basis] - tbl_pnl[total_fees_allocated]) -> 530551.89 | T28: =TEXT(E28,"mmm") -> Feb
A29: PF000002 | B29: COMP001 | C29: TR_SYN_0000170 | D29: TRD000017 | E29: 2025-06-17 | F29: 168 | G29: 756.52 | H29: 863 | I29: 652876.76 | J29: 420912.75 | K29: 210.46 | L29: 326.44 | M29: 536.9 | N29: 487.97591 | O29: 421123.21 | P29: 231427.11 | Q29: 0.54954727 | R29: 1 | S29: =(tbl_pnl[gross_sell_amount] - tbl_pnl[total_cost_basis] - tbl_pnl[total_fees_allocated]) -> 231216.65 | T29: =TEXT(E29,"mmm") -> Jun
A30: PF000002 | B30: COMP001 | C30: TR_SYN_0000079 | D30: TRD000007 | E30: 2025-05-16 | F30: 136 | G30: 783.17 | H30: 225 | I30: 176213.25 | J30: 176541.75 | K30: 88.272446 | L30: 88.11 | M30: 176.38245 | N30: 785.02232 | O30: 176630.02 | P30: -504.88245 | Q30: -0.0028584181 | R30: 0 | S30: =(tbl_pnl[gross_sell_amount] - tbl_pnl[total_cost_basis] - tbl_pnl[total_fees_allocated]) -> -593.15489 | T30: =TEXT(E30,"mmm") -> May
A31: PF000002 | B31: COMP002 | C31: TR_SYN_0000053 | D31: TRD000027 | E31: 2025-06-24 | F31: 175 | G31: 1285.55 | H31: 859 | I31: 1104287.4 | J31: 1072247.3 | K31: 536.12126 | L31: 552.14 | M31: 1088.2613 | N31: 1248.8748 | O31: 1072783.4 | P31: 30951.879 | Q31: 0.028851936 | R31: 1 | S31: =(tbl_pnl[gross_sell_amount] - tbl_pnl[total_cost_basis] - tbl_pnl[total_fees_allocated]) -> 30415.757 | T31: =TEXT(E31,"mmm") -> Jun
A32: PF000002 | B32: COMP003 | C32: TR_SYN_0000166 | D32: TRD000010 | E32: 2025-02-04 | F32: 35 | G32: 1961.49 | H32: 176 | I32: 345222.24 | J32: 0 | K32: 0 | L32: 172.61 | M32: 172.61 | N32: 0 | O32: 0 | P32: 345049.63 | Q32: 0 | R32: 1 | S32: =(tbl_pnl[gross_sell_amount] - tbl_pnl[total_cost_basis] - tbl_pnl[total_fees_allocated]) -> 345049.63 | T32: =TEXT(E32,"mmm") -> Feb
A33: PF000002 | B33: COMP003 | C33: TR_SYN_0000250 | D33: TRD000008 | E33: 2025-04-08 | F33: 98 | G33: 2196.27 | H33: 936 | I33: 2055708.7 | J33: 1103830.2 | K33: 551.92 | L33: 1027.85 | M33: 1579.77 | N33: 1179.8954 | O33: 1104382.1 | P33: 950298.75 | Q33: 0.86048002 | R33: 1 | S33: =(tbl_pnl[gross_sell_amount] - tbl_pnl[total_cost_basis] - tbl_pnl[total_fees_allocated]) -> 949746.83 | T33: =TEXT(E33,"mmm") -> Apr
A34: PF000002 | B34: COMP003 | C34: TR_SYN_0000447 | D34: TRD000012 | E34: 2025-05-06 | F34: 126 | G34: 2123.24 | H34: 234 | I34: 496838.16 | J34: 0 | K34: 0 | L34: 248.42 | M34: 248.42 | N34: 0 | O34: 0 | P34: 496589.74 | Q34: 0 | R34: 1 | S34: =(tbl_pnl[gross_sell_amount] - tbl_pnl[total_cost_basis] - tbl_pnl[total_fees_allocated]) -> 496589.74 | T34: =TEXT(E34,"mmm") -> May
A35: PF000002 | B35: COMP003 | C35: TR_SYN_0000459 | D35: TRD000010 | E35: 2025-04-25 | F35: 115 | G35: 2227.75 | H35: 624 | I35: 1390116 | J35: 975998.34 | K35: 488 | L35: 695.06 | M35: 1183.06 | N35: 1564.882 | O35: 976486.34 | P35: 412934.6 | Q35: 0.42287801 | R35: 1 | S35: =(tbl_pnl[gross_sell_amount] - tbl_pnl[total_cost_basis] - tbl_pnl[total_fees_allocated]) -> 412446.6 | T35: =TEXT(E35,"mmm") -> Apr
... A240: PF000010 | B240: COMP008 | C240: TR_SYN_0000219 | D240: TRD000002 | E240: 2025-02-28 | F240: 59 | G240: 1223.36 | H240: 786 | I240: 961560.96 | J240: 612835.2 | K240: 306.42 | L240: 480.78 | M240: 787.2 | N240: 780.0784 | O240: 613141.62 | P240: 347938.56 | Q240: 0.56746851 | R240: 1 | S240: =(tbl_pnl[gross_sell_amount] - tbl_pnl[total_cost_basis] - tbl_pnl[total_fees_allocated]) -> 347632.14 | T240: =TEXT(E240,"mmm") -> Feb

Sheet trading_analysis
A1: trade_id | B1: order_id | C1: trade_ts | D1: company_id | E1: side | F1: quantity | G1: price | H1: fees | I1: trader_id | J1: portfolio_id | K1: date | L1: Trader Name | M1: portfolio_name | N1: company_name | O1: Year | P1: Trade Value | Q1: Months | R1: Net Trade Value (after fees)
A2: TR_SYN_0000028 | B2: ORD00182 | C2: 2025-05-22 00:54:00 | D2: COMP007 | E2: SELL | F2: 627 | G2: 595.1 | H2: 186.56 | I2: TRD000015 | J2: PF000009 | K2: 2025-01-01 | L2: =VLOOKUP(I2,dim_trader!A:B,2,FALSE) -> Jamie Anderson | M2: =VLOOKUP(J2,dim_portfolio!A:B,2,FALSE) -> Portfolio 9 | N2: =VLOOKUP(D2,dim_company!A:C,3,FALSE) -> Amazon.com Inc. | O2: =VLOOKUP(K2,dim_calendar!A:C,3,FALSE) -> 2025 | P2: =(F2 * G2) -> 373127.7 | Q2: =TEXT(K2,"mmm") -> Jan | R2: =(F2 * G2) - H2 -> 372941.14 | S2: Total Trades:
A3: TR_SYN_0000036 | B3: ORD00241 | C3: 2025-05-01 00:22:00 | D3: COMP006 | E3: BUY | F3: 99 | G3: 236.11 | H3: 11.69 | I3: TRD000030 | J3: PF000003 | K3: 2025-01-01 | L3: =VLOOKUP(I3,dim_trader!A:B,2,FALSE) -> Riley Lee | M3: =VLOOKUP(J3,dim_portfolio!A:B,2,FALSE) -> Portfolio 3 | N3: =VLOOKUP(D3,dim_company!A:C,3,FALSE) -> Microsoft Corp. | O3: =VLOOKUP(K3,dim_calendar!A:C,3,FALSE) -> 2025 | P3: =(F3 * G3) -> 23374.89 | Q3: =TEXT(K3,"mmm") -> Jan | R3: =(F3 * G3) - H3 -> 23363.2 | S3: =COUNTA(A:A) -> 501
A4: TR_SYN_0000150 | B4: ORD00227 | C4: 2025-01-17 00:32:00 | D4: COMP003 | E4: BUY | F4: 817 | G4: 2048.3 | H4: 836.73 | I4: TRD000023 | J4: PF000005 | K4: 2025-01-01 | L4: =VLOOKUP(I4,dim_trader!A:B,2,FALSE) -> Rowan Harris | M4: =VLOOKUP(J4,dim_portfolio!A:B,2,FALSE) -> Portfolio 5 | N4: =VLOOKUP(D4,dim_company!A:C,3,FALSE) -> HDFC Bank | O4: =VLOOKUP(K4,dim_calendar!A:C,3,FALSE) -> 2025 | P4: =(F4 * G4) -> 1673461.1 | Q4: =TEXT(K4,"mmm") -> Jan | R4: =(F4 * G4) - H4 -> 1672624.4
A5: TR_SYN_0000353 | B5: ORD00259 | C5: 2025-06-27 00:05:00 | D5: COMP007 | E5: SELL | F5: 711 | G5: 585.7 | H5: 208.22 | I5: TRD000024 | J5: PF000004 | K5: 2025-01-01 | L5: =VLOOKUP(I5,dim_trader!A:B,2,FALSE) -> Taylor Wilson | M5: =VLOOKUP(J5,dim_portfolio!A:B,2,FALSE) -> Portfolio 4 | N5: =VLOOKUP(D5,dim_company!A:C,3,FALSE) -> Amazon.com Inc. | O5: =VLOOKUP(K5,dim_calendar!A:C,3,FALSE) -> 2025 | P5: =(F5 * G5) -> 416432.7 | Q5: =TEXT(K5,"mmm") -> Jan | R5: =(F5 * G5) - H5 -> 416224.48 | S5: Total Trade Value:
A6: TR_SYN_0000362 | B6: ORD00033 | C6: 2025-01-20 00:38:00 | D6: COMP008 | E6: BUY | F6: 65 | G6: 963.26 | H6: 31.31 | I6: TRD000013 | J6: PF000010 | K6: 2025-01-01 | L6: =VLOOKUP(I6,dim_trader!A:B,2,FALSE) -> Rowan Clark | M6: =VLOOKUP(J6,dim_portfolio!A:B,2,FALSE) -> Portfolio 10 | N6: =VLOOKUP(D6,dim_company!A:C,3,FALSE) -> Pfizer Inc. | O6: =VLOOKUP(K6,dim_calendar!A:C,3,FALSE) -> 2025 | P6: =(F6 * G6) -> 62611.9 | Q6: =TEXT(K6,"mmm") -> Jan | R6: =(F6 * G6) - H6 -> 62580.59 | S6: =SUM(P:P) -> 2.2058811e+08
A7: TR_SYN_0000435 | B7: ORD00432 | C7: 2025-05-19 00:01:00 | D7: COMP001 | E7: SELL | F7: 736 | G7: 818.2 | H7: 301.1 | I7: TRD000007 | J7: PF000008 | K7: 2025-01-01 | L7: =VLOOKUP(I7,dim_trader!A:B,2,FALSE) -> Alex Lee | M7: =VLOOKUP(J7,dim_portfolio!A:B,2,FALSE) -> Portfolio 8 | N7: =VLOOKUP(D7,dim_company!A:C,3,FALSE) -> Tata Consultancy Services | O7: =VLOOKUP(K7,dim_calendar!A:C,3,FALSE) -> 2025 | P7: =(F7 * G7) -> 602195.2 | Q7: =TEXT(K7,"mmm") -> Jan | R7: =(F7 * G7) - H7 -> 601894.1
A8: TR_SYN_0000009 | B8: ORD00374 | C8: 2025-06-26 00:03:00 | D8: COMP005 | E8: SELL | F8: 857 | G8: 255.49 | H8: 109.48 | I8: TRD000027 | J8: PF000009 | K8: 2025-01-02 | L8: =VLOOKUP(I8,dim_trader!A:B,2,FALSE) -> Elliot Clark | M8: =VLOOKUP(J8,dim_portfolio!A:B,2,FALSE) -> Portfolio 9 | N8: =VLOOKUP(D8,dim_company!A:C,3,FALSE) -> Apple Inc. | O8: =VLOOKUP(K8,dim_calendar!A:C,3,FALSE) -> 2025 | P8: =(F8 * G8) -> 218954.93 | Q8: =TEXT(K8,"mmm") -> Jan | R8: =(F8 * G8) - H8 -> 218845.45 | S8: Buy vs Sell %
A9: TR_SYN_0000018 | B9: ORD00471 | C9: 2025-04-30 00:03:00 | D9: COMP008 | E9: BUY | F9: 485 | G9: 1377.06 | H9: 333.94 | I9: TRD000004 | J9: PF000006 | K9: 2025-01-02 | L9: =VLOOKUP(I9,dim_trader!A:B,2,FALSE) -> Taylor Harris | M9: =VLOOKUP(J9,dim_portfolio!A:B,2,FALSE) -> Portfolio 6 | N9: =VLOOKUP(D9,dim_company!A:C,3,FALSE) -> Pfizer Inc. | O9: =VLOOKUP(K9,dim_calendar!A:C,3,FALSE) -> 2025 | P9: =(F9 * G9) -> 667874.1 | Q9: =TEXT(K9,"mmm") -> Jan | R9: =(F9 * G9) - H9 -> 667540.16
A10: TR_SYN_0000082 | B10: ORD00398 | C10: 2025-02-10 00:59:00 | D10: COMP006 | E10: BUY | F10: 135 | G10: 234.73 | H10: 15.84 | I10: TRD000021 | J10: PF000003 | K10: 2025-01-02 | L10: =VLOOKUP(I10,dim_trader!A:B,2,FALSE) -> Elliot Lewis | M10: =VLOOKUP(J10,dim_portfolio!A:B,2,FALSE) -> Portfolio 3 | N10: =VLOOKUP(D10,dim_company!A:C,3,FALSE) -> Microsoft Corp. | O10: =VLOOKUP(K10,dim_calendar!A:C,3,FALSE) -> 2025 | P10: =(F10 * G10) -> 31688.55 | Q10: =TEXT(K10,"mmm") -> Jan | R10: =(F10 * G10) - H10 -> 31672.71 | S10: Buy Trades
A11: TR_SYN_0000087 | B11: ORD00212 | C11: 2025-06-26 00:36:00 | D11: COMP007 | E11: SELL | F11: 218 | G11: 588.46 | H11: 64.14 | I11: TRD000001 | J11: PF000003 | K11: 2025-01-02 | L11: =VLOOKUP(I11,dim_trader!A:B,2,FALSE) -> Taylor Shah | M11: =VLOOKUP(J11,dim_portfolio!A:B,2,FALSE) -> Portfolio 3 | N11: =VLOOKUP(D11,dim_company!A:C,3,FALSE) -> Amazon.com Inc. | O11: =VLOOKUP(K11,dim_calendar!A:C,3,FALSE) -> 2025 | P11: =(F11 * G11) -> 128284.28 | Q11: =TEXT(K11,"mmm") -> Jan | R11: =(F11 * G11) - H11 -> 128220.14 | S11: =COUNTIF(E:E,"Buy") -> 261
A12: TR_SYN_0000114 | B12: ORD00050 | C12: 2025-04-03 00:46:00 | D12: COMP004 | E12: SELL | F12: 864 | G12: 648.78 | H12: 280.27 | I12: TRD000030 | J12: PF000008 | K12: 2025-01-02 | L12: =VLOOKUP(I12,dim_trader!A:B,2,FALSE) -> Riley Lee | M12: =VLOOKUP(J12,dim_portfolio!A:B,2,FALSE) -> Portfolio 8 | N12: =VLOOKUP(D12,dim_company!A:C,3,FALSE) -> Reliance Industries | O12: =VLOOKUP(K12,dim_calendar!A:C,3,FALSE) -> 2025 | P12: =(F12 * G12) -> 560545.92 | Q12: =TEXT(K12,"mmm") -> Jan | R12: =(F12 * G12) - H12 -> 560265.65
A13: TR_SYN_0000472 | B13: ORD00264 | C13: 2025-03-26 00:08:00 | D13: COMP003 | E13: BUY | F13: 792 | G13: 2162.29 | H13: 856.27 | I13: TRD000016 | J13: PF000005 | K13: 2025-01-02 | L13: =VLOOKUP(I13,dim_trader!A:B,2,FALSE) -> Hayden Brown | M13: =VLOOKUP(J13,dim_portfolio!A:B,2,FALSE) -> Portfolio 5 | N13: =VLOOKUP(D13,dim_company!A:C,3,FALSE) -> HDFC Bank | O13: =VLOOKUP(K13,dim_calendar!A:C,3,FALSE) -> 2025 | P13: =(F13 * G13) -> 1712533.7 | Q13: =TEXT(K13,"mmm") -> Jan | R13: =(F13 * G13) - H13 -> 1711677.4 | S13: Sell Trades
A14: TR_SYN_0000182 | B14: ORD00284 | C14: 2025-03-18 00:07:00 | D14: COMP004 | E14: BUY | F14: 989 | G14: 633.01 | H14: 313.02 | I14: TRD000024 | J14: PF000006 | K14: 2025-01-03 | L14: =VLOOKUP(I14,dim_trader!A:B,2,FALSE) -> Taylor Wilson | M14: =VLOOKUP(J14,dim_portfolio!A:B,2,FALSE) -> Portfolio 6 | N14: =VLOOKUP(D14,dim_company!A:C,3,FALSE) -> Reliance Industries | O14: =VLOOKUP(K14,dim_calendar!A:C,3,FALSE) -> 2025 | P14: =(F14 * G14) -> 626046.89 | Q14: =TEXT(K14,"mmm") -> Jan | R14: =(F14 * G14) - H14 -> 625733.87 | S14: =COUNTIF(E:E,"Sell") -> 239
A15: TR_SYN_0000090 | B15: ORD00206 | C15: 2025-05-14 00:02:00 | D15: COMP008 | E15: BUY | F15: 710 | G15: 1351.68 | H15: 479.85 | I15: TRD000029 | J15: PF000005 | K15: 2025-01-06 | L15: =VLOOKUP(I15,dim_trader!A:B,2,FALSE) -> Sam Williams | M15: =VLOOKUP(J15,dim_portfolio!A:B,2,FALSE) -> Portfolio 5 | N15: =VLOOKUP(D15,dim_company!A:C,3,FALSE) -> Pfizer Inc. | O15: =VLOOKUP(K15,dim_calendar!A:C,3,FALSE) -> 2025 | P15: =(F15 * G15) -> 959692.8 | Q15: =TEXT(K15,"mmm") -> Jan | R15: =(F15 * G15) - H15 -> 959212.95
A16: TR_SYN_0000135 | B16: ORD00063 | C16: 2025-03-07 00:14:00 | D16: COMP001 | E16: BUY | F16: 28 | G16: 754.8 | H16: 10.57 | I16: TRD000030 | J16: PF000008 | K16: 2025-01-06 | L16: =VLOOKUP(I16,dim_trader!A:B,2,FALSE) -> Riley Lee | M16: =VLOOKUP(J16,dim_portfolio!A:B,2,FALSE) -> Portfolio 8 | N16: =VLOOKUP(D16,dim_company!A:C,3,FALSE) -> Tata Consultancy Services | O16: =VLOOKUP(K16,dim_calendar!A:C,3,FALSE) -> 2025 | P16: =(F16 * G16) -> 21134.4 | Q16: =TEXT(K16,"mmm") -> Jan | R16: =(F16 * G16) - H16 -> 21123.83 | S16: Buy %
A17: TR_SYN_0000157 | B17: ORD00229 | C17: 2025-04-29 00:47:00 | D17: COMP001 | E17: BUY | F17: 719 | G17: 833.74 | H17: 299.73 | I17: TRD000025 | J17: PF000007 | K17: 2025-01-06 | L17: =VLOOKUP(I17,dim_trader!A:B,2,FALSE) -> Jordan Harris | M17: =VLOOKUP(J17,dim_portfolio!A:B,2,FALSE) -> Portfolio 7 | N17: =VLOOKUP(D17,dim_company!A:C,3,FALSE) -> Tata Consultancy Services | O17: =VLOOKUP(K17,dim_calendar!A:C,3,FALSE) -> 2025 | P17: =(F17 * G17) -> 599459.06 | Q17: =TEXT(K17,"mmm") -> Jan | R17: =(F17 * G17) - H17 -> 599159.33 | S17: =S11 / (S11 + S14) -> 0.522
A18: TR_SYN_0000360 | B18: ORD00192 | C18: 2025-03-14 00:55:00 | D18: COMP004 | E18: SELL | F18: 666 | G18: 643.51 | H18: 214.29 | I18: TRD000014 | J18: PF000008 | K18: 2025-01-06 | L18: =VLOOKUP(I18,dim_trader!A:B,2,FALSE) -> Drew Shah | M18: =VLOOKUP(J18,dim_portfolio!A:B,2,FALSE) -> Portfolio 8 | N18: =VLOOKUP(D18,dim_company!A:C,3,FALSE) -> Reliance Industries | O18: =VLOOKUP(K18,dim_calendar!A:C,3,FALSE) -> 2025 | P18: =(F18 * G18) -> 428577.66 | Q18: =TEXT(K18,"mmm") -> Jan | R18: =(F18 * G18) - H18 -> 428363.37
A19: TR_SYN_0000376 | B19: ORD00474 | C19: 2025-05-15 00:51:00 | D19: COMP007 | E19: SELL | F19: 801 | G19: 591.8 | H19: 237.02 | I19: TRD000024 | J19: PF000007 | K19: 2025-01-06 | L19: =VLOOKUP(I19,dim_trader!A:B,2,FALSE) -> Taylor Wilson | M19: =VLOOKUP(J19,dim_portfolio!A:B,2,FALSE) -> Portfolio 7 | N19: =VLOOKUP(D19,dim_company!A:C,3,FALSE) -> Amazon.com Inc. | O19: =VLOOKUP(K19,dim_calendar!A:C,3,FALSE) -> 2025 | P19: =(F19 * G19) -> 474031.8 | Q19: =TEXT(K19,"mmm") -> Jan | R19: =(F19 * G19) - H19 -> 473794.78
A20: TR_SYN_0000126 | B20: ORD00187 | C20: 2025-03-28 00:29:00 | D20: COMP005 | E20: BUY | F20: 652 | G20: 243.97 | H20: 79.53 | I20: TRD000017 | J20: PF000002 | K20: 2025-01-07 | L20: =VLOOKUP(I20,dim_trader!A:B,2,FALSE) -> Casey Khan | M20: =VLOOKUP(J20,dim_portfolio!A:B,2,FALSE) -> Portfolio 2 | N20: =VLOOKUP(D20,dim_company!A:C,3,FALSE) -> Apple Inc. | O20: =VLOOKUP(K20,dim_calendar!A:C,3,FALSE) -> 2025 | P20: =(F20 * G20) -> 159068.44 | Q20: =TEXT(K20,"mmm") -> Jan | R20: =(F20 * G20) - H20 -> 158988.91 | S20: Avg Trade Size
A21: TR_SYN_0000299 | B21: ORD00426 | C21: 2025-03-11 00:30:00 | D21: COMP001 | E21: BUY | F21: 175 | G21: 769.58 | H21: 67.34 | I21: TRD000008 | J21: PF000008 | K21: 2025-01-07 | L21: =VLOOKUP(I21,dim_trader!A:B,2,FALSE) -> Morgan Williams | M21: =VLOOKUP(J21,dim_portfolio!A:B,2,FALSE) -> Portfolio 8 | N21: =VLOOKUP(D21,dim_company!A:C,3,FALSE) -> Tata Consultancy Services | O21: =VLOOKUP(K21,dim_calendar!A:C,3,FALSE) -> 2025 | P21: =(F21 * G21) -> 134676.5 | Q21: =TEXT(K21,"mmm") -> Jan | R21: =(F21 * G21) - H21 -> 134609.16 | S21: =AVERAGE(P:P) -> 441176.23
A22: TR_SYN_0000378 | B22: ORD00118 | C22: 2025-02-28 00:19:00 | D22: COMP002 | E22: SELL | F22: 550 | G22: 1268.87 | H22: 348.94 | I22: TRD000008 | J22: PF000006 | K22: 2025-01-07 | L22: =VLOOKUP(I22,dim_trader!A:B,2,FALSE) -> Morgan Williams | M22: =VLOOKUP(J22,dim_portfolio!A:B,2,FALSE) -> Portfolio 6 | N22: =VLOOKUP(D22,dim_company!A:C,3,FALSE) -> Infosys | O22: =VLOOKUP(K22,dim_calendar!A:C,3,FALSE) -> 2025 | P22: =(F22 * G22) -> 697878.5 | Q22: =TEXT(K22,"mmm") -> Jan | R22: =(F22 * G22) - H22 -> 697529.56
A23: TR_SYN_0000493 | B23: ORD00125 | C23: 2025-05-22 00:33:00 | D23: COMP002 | E23: BUY | F23: 432 | G23: 1252.39 | H23: 270.52 | I23: TRD000008 | J23: PF000009 | K23: 2025-01-07 | L23: =VLOOKUP(I23,dim_trader!A:B,2,FALSE) -> Morgan Williams | M23: =VLOOKUP(J23,dim_portfolio!A:B,2,FALSE) -> Portfolio 9 | N23: =VLOOKUP(D23,dim_company!A:C,3,FALSE) -> Infosys | O23: =VLOOKUP(K23,dim_calendar!A:C,3,FALSE) -> 2025 | P23: =(F23 * G23) -> 541032.48 | Q23: =TEXT(K23,"mmm") -> Jan | R23: =(F23 * G23) - H23 -> 540761.96
A24: TR_SYN_0000092 | B24: ORD00457 | C24: 2025-05-07 00:15:00 | D24: COMP004 | E24: SELL | F24: 319 | G24: 664.41 | H24: 105.97 | I24: TRD000028 | J24: PF000008 | K24: 2025-01-08 | L24: =VLOOKUP(I24,dim_trader!A:B,2,FALSE) -> Morgan Lee | M24: =VLOOKUP(J24,dim_portfolio!A:B,2,FALSE) -> Portfolio 8 | N24: =VLOOKUP(D24,dim_company!A:C,3,FALSE) -> Reliance Industries | O24: =VLOOKUP(K24,dim_calendar!A:C,3,FALSE) -> 2025 | P24: =(F24 * G24) -> 211946.79 | Q24: =TEXT(K24,"mmm") -> Jan | R24: =(F24 * G24) - H24 -> 211840.82
A25: TR_SYN_0000118 | B25: ORD00040 | C25: 2025-06-26 00:34:00 | D25: COMP005 | E25: BUY | F25: 301 | G25: 254.6 | H25: 38.32 | I25: TRD000006 | J25: PF000008 | K25: 2025-01-08 | L25: =VLOOKUP(I25,dim_trader!A:B,2,FALSE) -> Reese Patel | M25: =VLOOKUP(J25,dim_portfolio!A:B,2,FALSE) -> Portfolio 8 | N25: =VLOOKUP(D25,dim_company!A:C,3,FALSE) -> Apple Inc. | O25: =VLOOKUP(K25,dim_calendar!A:C,3,FALSE) -> 2025 | P25: =(F25 * G25) -> 76634.6 | Q25: =TEXT(K25,"mmm") -> Jan | R25: =(F25 * G25) - H25 -> 76596.28
A26: TR_SYN_0000486 | B26: ORD00331 | C26: 2025-04-04 00:02:00 | D26: COMP008 | E26: BUY | F26: 515 | G26: 1214.01 | H26: 312.61 | I26: TRD000013 | J26: PF000005 | K26: 2025-01-08 | L26: =VLOOKUP(I26,dim_trader!A:B,2,FALSE) -> Rowan Clark | M26: =VLOOKUP(J26,dim_portfolio!A:B,2,FALSE) -> Portfolio 5 | N26: =VLOOKUP(D26,dim_company!A:C,3,FALSE) -> Pfizer Inc. | O26: =VLOOKUP(K26,dim_calendar!A:C,3,FALSE) -> 2025 | P26: =(F26 * G26) -> 625215.15 | Q26: =TEXT(K26,"mmm") -> Jan | R26: =(F26 * G26) - H26 -> 624902.54
A27: TR_SYN_0000214 | B27: ORD00385 | C27: 2025-06-27 00:52:00 | D27: COMP006 | E27: BUY | F27: 528 | G27: 224.41 | H27: 59.24 | I27: TRD000018 | J27: PF000006 | K27: 2025-01-09 | L27: =VLOOKUP(I27,dim_trader!A:B,2,FALSE) -> Hayden Nguyen | M27: =VLOOKUP(J27,dim_portfolio!A:B,2,FALSE) -> Portfolio 6 | N27: =VLOOKUP(D27,dim_company!A:C,3,FALSE) -> Microsoft Corp. | O27: =VLOOKUP(K27,dim_calendar!A:C,3,FALSE) -> 2025 | P27: =(F27 * G27) -> 118488.48 | Q27: =TEXT(K27,"mmm") -> Jan | R27: =(F27 * G27) - H27 -> 118429.24
A28: TR_SYN_0000398 | B28: ORD00193 | C28: 2025-01-30 00:45:00 | D28: COMP001 | E28: BUY | F28: 847 | G28: 755.81 | H28: 320.09 | I28: TRD000028 | J28: PF000001 | K28: 2025-01-09 | L28: =VLOOKUP(I28,dim_trader!A:B,2,FALSE) -> Morgan Lee | M28: =VLOOKUP(J28,dim_portfolio!A:B,2,FALSE) -> Portfolio 1 | N28: =VLOOKUP(D28,dim_company!A:C,3,FALSE) -> Tata Consultancy Services | O28: =VLOOKUP(K28,dim_calendar!A:C,3,FALSE) -> 2025 | P28: =(F28 * G28) -> 640171.07 | Q28: =TEXT(K28,"mmm") -> Jan | R28: =(F28 * G28) - H28 -> 639850.98
A29: TR_SYN_0000400 | B29: ORD00126 | C29: 2025-06-20 00:07:00 | D29: COMP003 | E29: BUY | F29: 148 | G29: 2172.35 | H29: 160.75 | I29: TRD000006 | J29: PF000001 | K29: 2025-01-09 | L29: =VLOOKUP(I29,dim_trader!A:B,2,FALSE) -> Reese Patel | M29: =VLOOKUP(J29,dim_portfolio!A:B,2,FALSE) -> Portfolio 1 | N29: =VLOOKUP(D29,dim_company!A:C,3,FALSE) -> HDFC Bank | O29: =VLOOKUP(K29,dim_calendar!A:C,3,FALSE) -> 2025 | P29: =(F29 * G29) -> 321507.8 | Q29: =TEXT(K29,"mmm") -> Jan | R29: =(F29 * G29) - H29 -> 321347.05
A30: TR_SYN_0000076 | B30: ORD00054 | C30: 2025-02-12 00:37:00 | D30: COMP007 | E30: BUY | F30: 443 | G30: 541.88 | H30: 120.03 | I30: TRD000013 | J30: PF000008 | K30: 2025-01-10 | L30: =VLOOKUP(I30,dim_trader!A:B,2,FALSE) -> Rowan Clark | M30: =VLOOKUP(J30,dim_portfolio!A:B,2,FALSE) -> Portfolio 8 | N30: =VLOOKUP(D30,dim_company!A:C,3,FALSE) -> Amazon.com Inc. | O30: =VLOOKUP(K30,dim_calendar!A:C,3,FALSE) -> 2025 | P30: =(F30 * G30) -> 240052.84 | Q30: =TEXT(K30,"mmm") -> Jan | R30: =(F30 * G30) - H30 -> 239932.81
A31: TR_SYN_0000094 | B31: ORD00255 | C31: 2025-04-29 00:03:00 | D31: COMP004 | E31: BUY | F31: 944 | G31: 667.56 | H31: 315.09 | I31: TRD000024 | J31: PF000006 | K31: 2025-01-10 | L31: =VLOOKUP(I31,dim_trader!A:B,2,FALSE) -> Taylor Wilson | M31: =VLOOKUP(J31,dim_portfolio!A:B,2,FALSE) -> Portfolio 6 | N31: =VLOOKUP(D31,dim_company!A:C,3,FALSE) -> Reliance Industries | O31: =VLOOKUP(K31,dim_calendar!A:C,3,FALSE) -> 2025 | P31: =(F31 * G31) -> 630176.64 | Q31: =TEXT(K31,"mmm") -> Jan | R31: =(F31 * G31) - H31 -> 629861.55
A32: TR_SYN_0000215 | B32: ORD00166 | C32: 2025-03-14 00:39:00 | D32: COMP004 | E32: SELL | F32: 920 | G32: 644.04 | H32: 296.26 | I32: TRD000016 | J32: PF000008 | K32: 2025-01-10 | L32: =VLOOKUP(I32,dim_trader!A:B,2,FALSE) -> Hayden Brown | M32: =VLOOKUP(J32,dim_portfolio!A:B,2,FALSE) -> Portfolio 8 | N32: =VLOOKUP(D32,dim_company!A:C,3,FALSE) -> Reliance Industries | O32: =VLOOKUP(K32,dim_calendar!A:C,3,FALSE) -> 2025 | P32: =(F32 * G32) -> 592516.8 | Q32: =TEXT(K32,"mmm") -> Jan | R32: =(F32 * G32) - H32 -> 592220.54
A33: TR_SYN_0000404 | B33: ORD00428 | C33: 2025-01-31 00:47:00 | D33: COMP005 | E33: BUY | F33: 56 | G33: 230.29 | H33: 6.45 | I33: TRD000009 | J33: PF000010 | K33: 2025-01-10 | L33: =VLOOKUP(I33,dim_trader!A:B,2,FALSE) -> Robin Lewis | M33: =VLOOKUP(J33,dim_portfolio!A:B,2,FALSE) -> Portfolio 10 | N33: =VLOOKUP(D33,dim_company!A:C,3,FALSE) -> Apple Inc. | O33: =VLOOKUP(K33,dim_calendar!A:C,3,FALSE) -> 2025 | P33: =(F33 * G33) -> 12896.24 | Q33: =TEXT(K33,"mmm") -> Jan | R33: =(F33 * G33) - H33 -> 12889.79
... A501: TR_SYN_0000462 | B501: ORD00492 | C501: 2025-06-03 00:58:00 | D501: COMP007 | E501: BUY | F501: 991 | G501: 615.47 | H501: 304.97 | I501: TRD000029 | J501: PF000005 | K501: 2025-06-30 | L501: =VLOOKUP(I501,dim_trader!A:B,2,FALSE) -> Sam Williams | M501: =VLOOKUP(J501,dim_portfolio!A:B,2,FALSE) -> Portfolio 5 | N501: =VLOOKUP(D501,dim_company!A:C,3,FALSE) -> Amazon.com Inc. | O501: =VLOOKUP(K501,dim_calendar!A:C,3,FALSE) -> 2025 | P501: =(F501 * G501) -> 609930.77 | Q501: =TEXT(K501,"mmm") -> Jun | R501: =(F501 * G501) - H501 -> 609625.8

Sheet market_analysis
A1: date | B1: company_id | C1: open | D1: high | E1: low | F1: close | G1: volume | H1: company_name | I1: sector_id | J1: sector_name | K1: daily_change | L1: Daily % Change | M1: Volatility | N1: Months
A2: 2025-01-01 | B2: COMP001 | C2: 796.56 | D2: 800.79 | E2: 792.33 | F2: 800.53 | G2: 42106 | H2: =VLOOKUP(B2,dim_company!A:C,3,FALSE) -> Tata Consultancy Services | I2: =VLOOKUP(B2,dim_company!A:D,4,FALSE) -> SEC01 | J2: =VLOOKUP(I2,dim_sector!A:B,2,FALSE) -> Information Technology | K2: =tbl_market[[#This Row],[close]] - tbl_market[[#This Row],[open]] -> 3.97 | L2: =(tbl_market[ [#This Row],[close] ] - tbl_market[[#This Row],[open]]) / tbl_market[[#This Row],[open]] -> 0.0049839309 | M2: =tbl_market[[#This Row],[high]] - tbl_market[[#This Row],[low]] -> 8.46 | N2: =TEXT(A2,"mmm") -> Jan | O2: Avg Daily Return %
A3: 2025-01-02 | B3: COMP001 | C3: 805.97 | D3: 809.55 | E3: 802.39 | F3: 803.94 | G3: 9680 | H3: =VLOOKUP(B3,dim_company!A:C,3,FALSE) -> Tata Consultancy Services | I3: =VLOOKUP(B3,dim_company!A:D,4,FALSE) -> SEC01 | J3: =VLOOKUP(I3,dim_sector!A:B,2,FALSE) -> Information Technology | K3: =tbl_market[[#This Row],[close]] - tbl_market[[#This Row],[open]] -> -2.03 | L3: =(tbl_market[ [#This Row],[close] ] - tbl_market[[#This Row],[open]]) / tbl_market[[#This Row],[open]] -> -0.0025187042 | M3: =tbl_market[[#This Row],[high]] - tbl_market[[#This Row],[low]] -> 7.16 | N3: =TEXT(A3,"mmm") -> Jan | O3: =AVERAGE(L:L) -> -7.5109388e-05
A4: 2025-01-03 | B4: COMP001 | C4: 809.42 | D4: 818.12 | E4: 800.72 | F4: 806.96 | G4: 36153 | H4: =VLOOKUP(B4,dim_company!A:C,3,FALSE) -> Tata Consultancy Services | I4: =VLOOKUP(B4,dim_company!A:D,4,FALSE) -> SEC01 | J4: =VLOOKUP(I4,dim_sector!A:B,2,FALSE) -> Information Technology | K4: =tbl_market[[#This Row],[close]] - tbl_market[[#This Row],[open]] -> -2.46 | L4: =(tbl_market[ [#This Row],[close] ] - tbl_market[[#This Row],[open]]) / tbl_market[[#This Row],[open]] -> -0.0030392133 | M4: =tbl_market[[#This Row],[high]] - tbl_market[[#This Row],[low]] -> 17.4 | N4: =TEXT(A4,"mmm") -> Jan
A5: 2025-01-06 | B5: COMP001 | C5: 818.82 | D5: 831.19 | E5: 806.45 | F5: 817.5 | G5: 9120 | H5: =VLOOKUP(B5,dim_company!A:C,3,FALSE) -> Tata Consultancy Services | I5: =VLOOKUP(B5,dim_company!A:D,4,FALSE) -> SEC01 | J5: =VLOOKUP(I5,dim_sector!A:B,2,FALSE) -> Information Technology | K5: =tbl_market[[#This Row],[close]] - tbl_market[[#This Row],[open]] -> -1.32 | L5: =(tbl_market[ [#This Row],[close] ] - tbl_market[[#This Row],[open]]) / tbl_market[[#This Row],[open]] -> -0.0016120759 | M5: =tbl_market[[#This Row],[high]] - tbl_market[[#This Row],[low]] -> 24.74 | N5: =TEXT(A5,"mmm") -> Jan | O5: Max Gain Day:
A6: 2025-01-07 | B6: COMP001 | C6: 805.15 | D6: 813.57 | E6: 796.72 | F6: 811.73 | G6: 21445 | H6: =VLOOKUP(B6,dim_company!A:C,3,FALSE) -> Tata Consultancy Services | I6: =VLOOKUP(B6,dim_company!A:D,4,FALSE) -> SEC01 | J6: =VLOOKUP(I6,dim_sector!A:B,2,FALSE) -> Information Technology | K6: =tbl_market[[#This Row],[close]] - tbl_market[[#This Row],[open]] -> 6.58 | L6: =(tbl_market[ [#This Row],[close] ] - tbl_market[[#This Row],[open]]) / tbl_market[[#This Row],[open]] -> 0.0081723902 | M6: =tbl_market[[#This Row],[high]] - tbl_market[[#This Row],[low]] -> 16.85 | N6: =TEXT(A6,"mmm") -> Jan | O6: =MAX(L:L) -> 0.0099027268
A7: 2025-01-08 | B7: COMP001 | C7: 810.34 | D7: 817.79 | E7: 802.88 | F7: 806.57 | G7: 32065 | H7: =VLOOKUP(B7,dim_company!A:C,3,FALSE) -> Tata Consultancy Services | I7: =VLOOKUP(B7,dim_company!A:D,4,FALSE) -> SEC01 | J7: =VLOOKUP(I7,dim_sector!A:B,2,FALSE) -> Information Technology | K7: =tbl_market[[#This Row],[close]] - tbl_market[[#This Row],[open]] -> -3.77 | L7: =(tbl_market[ [#This Row],[close] ] - tbl_market[[#This Row],[open]]) / tbl_market[[#This Row],[open]] -> -0.0046523681 | M7: =tbl_market[[#This Row],[high]] - tbl_market[[#This Row],[low]] -> 14.91 | N7: =TEXT(A7,"mmm") -> Jan
A8: 2025-01-09 | B8: COMP001 | C8: 804.7 | D8: 816.71 | E8: 792.7 | F8: 800.97 | G8: 46936 | H8: =VLOOKUP(B8,dim_company!A:C,3,FALSE) -> Tata Consultancy Services | I8: =VLOOKUP(B8,dim_company!A:D,4,FALSE) -> SEC01 | J8: =VLOOKUP(I8,dim_sector!A:B,2,FALSE) -> Information Technology | K8: =tbl_market[[#This Row],[close]] - tbl_market[[#This Row],[open]] -> -3.73 | L8: =(tbl_market[ [#This Row],[close] ] - tbl_market[[#This Row],[open]]) / tbl_market[[#This Row],[open]] -> -0.0046352678 | M8: =tbl_market[[#This Row],[high]] - tbl_market[[#This Row],[low]] -> 24.01 | N8: =TEXT(A8,"mmm") -> Jan | O8: Max Loss Day:
A9: 2025-01-10 | B9: COMP001 | C9: 793.07 | D9: 795.72 | E9: 790.42 | F9: 791.89 | G9: 21932 | H9: =VLOOKUP(B9,dim_company!A:C,3,FALSE) -> Tata Consultancy Services | I9: =VLOOKUP(B9,dim_company!A:D,4,FALSE) -> SEC01 | J9: =VLOOKUP(I9,dim_sector!A:B,2,FALSE) -> Information Technology | K9: =tbl_market[[#This Row],[close]] - tbl_market[[#This Row],[open]] -> -1.18 | L9: =(tbl_market[ [#This Row],[close] ] - tbl_market[[#This Row],[open]]) / tbl_market[[#This Row],[open]] -> -0.0014878888 | M9: =tbl_market[[#This Row],[high]] - tbl_market[[#This Row],[low]] -> 5.3 | N9: =TEXT(A9,"mmm") -> Jan | O9: =MIN(L:L) -> -0.0095118424
A10: 2025-01-13 | B10: COMP001 | C10: 768.48 | D10: 780.24 | E10: 756.73 | F10: 766.43 | G10: 44016 | H10: =VLOOKUP(B10,dim_company!A:C,3,FALSE) -> Tata Consultancy Services | I10: =VLOOKUP(B10,dim_company!A:D,4,FALSE) -> SEC01 | J10: =VLOOKUP(I10,dim_sector!A:B,2,FALSE) -> Information Technology | K10: =tbl_market[[#This Row],[close]] - tbl_market[[#This Row],[open]] -> -2.05 | L10: =(tbl_market[ [#This Row],[close] ] - tbl_market[[#This Row],[open]]) / tbl_market[[#This Row],[open]] -> -0.0026676036 | M10: =tbl_market[[#This Row],[high]] - tbl_market[[#This Row],[low]] -> 23.51 | N10: =TEXT(A10,"mmm") -> Jan
A11: 2025-01-14 | B11: COMP001 | C11: 772.58 | D11: 780.18 | E11: 764.98 | F11: 775.85 | G11: 2154 | H11: =VLOOKUP(B11,dim_company!A:C,3,FALSE) -> Tata Consultancy Services | I11: =VLOOKUP(B11,dim_company!A:D,4,FALSE) -> SEC01 | J11: =VLOOKUP(I11,dim_sector!A:B,2,FALSE) -> Information Technology | K11: =tbl_market[[#This Row],[close]] - tbl_market[[#This Row],[open]] -> 3.27 | L11: =(tbl_market[ [#This Row],[close] ] - tbl_market[[#This Row],[open]]) / tbl_market[[#This Row],[open]] -> 0.0042325714 | M11: =tbl_market[[#This Row],[high]] - tbl_market[[#This Row],[low]] -> 15.2 | N11: =TEXT(A11,"mmm") -> Jan | O11: Avg Volume:
A12: 2025-01-15 | B12: COMP001 | C12: 787.6 | D12: 797.49 | E12: 777.72 | F12: 784.06 | G12: 13183 | H12: =VLOOKUP(B12,dim_company!A:C,3,FALSE) -> Tata Consultancy Services | I12: =VLOOKUP(B12,dim_company!A:D,4,FALSE) -> SEC01 | J12: =VLOOKUP(I12,dim_sector!A:B,2,FALSE) -> Information Technology | K12: =tbl_market[[#This Row],[close]] - tbl_market[[#This Row],[open]] -> -3.54 | L12: =(tbl_market[ [#This Row],[close] ] - tbl_market[[#This Row],[open]]) / tbl_market[[#This Row],[open]] -> -0.0044946673 | M12: =tbl_market[[#This Row],[high]] - tbl_market[[#This Row],[low]] -> 19.77 | N12: =TEXT(A12,"mmm") -> Jan | O12: =AVERAGE(G:G) -> 25414.797
A13: 2025-01-16 | B13: COMP001 | C13: 768.68 | D13: 782.43 | E13: 754.94 | F13: 769.33 | G13: 6539 | H13: =VLOOKUP(B13,dim_company!A:C,3,FALSE) -> Tata Consultancy Services | I13: =VLOOKUP(B13,dim_company!A:D,4,FALSE) -> SEC01 | J13: =VLOOKUP(I13,dim_sector!A:B,2,FALSE) -> Information Technology | K13: =tbl_market[[#This Row],[close]] - tbl_market[[#This Row],[open]] -> 0.65 | L13: =(tbl_market[ [#This Row],[close] ] - tbl_market[[#This Row],[open]]) / tbl_market[[#This Row],[open]] -> 0.00084560545 | M13: =tbl_market[[#This Row],[high]] - tbl_market[[#This Row],[low]] -> 27.49 | N13: =TEXT(A13,"mmm") -> Jan
A14: 2025-01-17 | B14: COMP001 | C14: 767.61 | D14: 779.13 | E14: 756.09 | F14: 765.38 | G14: 49354 | H14: =VLOOKUP(B14,dim_company!A:C,3,FALSE) -> Tata Consultancy Services | I14: =VLOOKUP(B14,dim_company!A:D,4,FALSE) -> SEC01 | J14: =VLOOKUP(I14,dim_sector!A:B,2,FALSE) -> Information Technology | K14: =tbl_market[[#This Row],[close]] - tbl_market[[#This Row],[open]] -> -2.23 | L14: =(tbl_market[ [#This Row],[close] ] - tbl_market[[#This Row],[open]]) / tbl_market[[#This Row],[open]] -> -0.0029051211 | M14: =tbl_market[[#This Row],[high]] - tbl_market[[#This Row],[low]] -> 23.04 | N14: =TEXT(A14,"mmm") -> Jan
A15: 2025-01-20 | B15: COMP001 | C15: 754.13 | D15: 764.08 | E15: 744.17 | F15: 758.43 | G15: 3200 | H15: =VLOOKUP(B15,dim_company!A:C,3,FALSE) -> Tata Consultancy Services | I15: =VLOOKUP(B15,dim_company!A:D,4,FALSE) -> SEC01 | J15: =VLOOKUP(I15,dim_sector!A:B,2,FALSE) -> Information Technology | K15: =tbl_market[[#This Row],[close]] - tbl_market[[#This Row],[open]] -> 4.3 | L15: =(tbl_market[ [#This Row],[close] ] - tbl_market[[#This Row],[open]]) / tbl_market[[#This Row],[open]] -> 0.0057019347 | M15: =tbl_market[[#This Row],[high]] - tbl_market[[#This Row],[low]] -> 19.91 | N15: =TEXT(A15,"mmm") -> Jan
